<mujoco model="piper_calibration">
    <compiler angle="radian" coordinate="local"/>
    <option timestep="0.002"/>
    <size njmax="500" nconmax="100"/>
    <visual>
        <global offheight="640" offwidth="640"/>
    </visual>

    <asset>
        <texture name="checker_tex" type="2d" file="/home/ubuntu/3d_proj/checkerboard_bordered.png" builtin="none"/>
        <material name="checker_mat" texture="checker_tex" texrepeat="1 1" />
        <mesh name="base_link" file="meshes/base_link.STL" />
        <mesh name="link1" file="meshes/link1.STL" />
        <mesh name="link2" file="meshes/link2.STL" />
        <mesh name="link3" file="meshes/link3.STL" />
        <mesh name="link4" file="meshes/link4.STL" />
        <mesh name="link5" file="meshes/link5.STL" />
        <mesh name="link6" file="meshes/link6.STL" />
        <mesh name="gripper_base" file="meshes/gripper_base.STL" />
        <mesh name="link7" file="meshes/link7.STL" />
        <mesh name="link8" file="meshes/link8.STL" />
    </asset>

    <worldbody>
        <body name="gt_marker_body" mocap="true">
                <site name="marker_true" type="sphere" size="0.01" rgba="0 1 0 1"/>
            </body>
            <body name="pred_marker_body" mocap="true">
                <site name="marker_est" type="sphere" size="0.01" rgba="1 0 0 1"/>
        </body>


        <light name="light0" pos="0 0 1" dir="0 0 -1" diffuse="1 1 1" specular="0.3 0.3 0.3" castshadow="false"/>

        <!-- Overhead fixed camera for Eye-to-Hand -->
        <camera name="fixed_cam" pos="0 0 1.0" quat="0.7071 0 0 0.7071" fovy="80"/>


        <!-- Robot base -->
        <geom type="mesh" rgba="0.792157 0.819608 0.933333 1" mesh="base_link" />
        <body name="link1" pos="0 0 0.123">
            <joint name="joint1" pos="0 0 0" axis="0 0 1" limited="true" range="-2.618 2.168" damping="500"/>
            <geom type="mesh" mesh="link1" />
            <body name="link2" pos="0 0 0" quat="0.0356735 -0.0356786 -0.706207 -0.706205">
                <joint name="joint2" pos="0 0 0" axis="0 0 1" limited="true" range="0 3.14" damping="5"/>
                <geom type="mesh" mesh="link2" />
                <body name="link3" pos="0.28503 0 0" quat="0.637536 0 0 -0.77042">
                    <joint name="joint3" pos="0 0 0" axis="0 0 1" limited="true" range="-2.967 0" damping="20"/>
                    <geom type="mesh" mesh="link3" />
                    <body name="link4" pos="-0.021984 -0.25075 0" quat="0.707105 0.707108 0 0">
                        <joint name="joint4" pos="0 0 0" axis="0 0 1" limited="true" range="-1.745 1.745" damping="5"/>
                        <geom type="mesh" mesh="link4" />
                        <body name="link5" pos="0 0 0" quat="0.707105 -0.707108 0 0">
                            <joint name="joint5" pos="0 0 0" axis="0 0 1" limited="true" range="-1.22 1.22" damping="5"/>
                            <geom type="mesh" mesh="link5" />
                            <body name="link6" pos="8.8259e-05 -0.091 0" quat="0.707105 0.707108 0 0">
                                <joint name="joint6" pos="0 0 0" axis="0 0 1" limited="true" range="-2.0944 2.0944" damping="5"/>
                                <geom type="mesh" mesh="link6" />
                                <geom type="mesh" mesh="gripper_base" />

                                <!-- ✅ Checkerboard now attached to end-effector -->
                                <body name="checkerboard_mount" pos="0 0 0.22">
                                    <geom name="checker_geom" type="box" size="0.15 0.2 0.001" material="checker_mat"/>
                                </body>

                                <!-- (Optional) Still includes Eye-in-Hand camera -->
                                <body name="ee_camera_mount" pos="0 0 0.22">
                                    <camera name="ee_cam" pos="0 0 0" euler="1.58 0 0" fovy="80"/>
                                    <!-- <geom name="cam_ray" type="capsule" size="0.005 0.2" pos="0 0.1 0"
                                          rgba="1 0 0 1" euler="1.57 0 0"/> -->
                                </body>

                                <body name="link7" pos="0 0 0.1358" quat="0.707105 0.707108 0 0">
                                    <joint name="joint7" pos="0 0 0" axis="0 0 1" type="slide" limited="true" range="0 0.035" damping="100"/>
                                    <geom type="mesh" mesh="link7" />
                                </body>
                                <body name="link8" pos="0 0 0.1358" quat="-2.59734e-06 -2.59735e-06 -0.707108 -0.707105">
                                    <joint name="joint8" pos="0 0 0" axis="0 0 -1" type="slide" limited="true" range="-0.035 0" damping="100"/>
                                    <geom type="mesh" mesh="link8" />
                                </body>
                            </body>
                        </body>
                    </body>
                </body>
            </body>
        </body>
    </worldbody>

    <actuator>
        <position name="joint1" joint="joint1" kp="10000" ctrlrange="-2.618 2.618" ctrllimited="true"/>
        <position name="joint2" joint="joint2" kp="2000" ctrlrange="0 3.14158" ctrllimited="true"/>
        <position name="joint3" joint="joint3" kp="2000" ctrlrange="-2.697 0" ctrllimited="true"/>
        <position name="joint4" joint="joint4" kp="500" ctrlrange="-1.832 1.832" ctrllimited="true"/>
        <position name="joint5" joint="joint5" kp="200" ctrlrange="-1.22 1.22" ctrllimited="true"/>
        <position name="joint6" joint="joint6" kp="200" ctrlrange="-3.14158 3.14158" ctrllimited="true"/>
        <position name="joint7" joint="joint7" kp="10000" ctrlrange="0 0.0475" ctrllimited="true"/>
        <position name="joint8" joint="joint8" kp="10000" ctrlrange="-0.0475 0" ctrllimited="true"/>
    </actuator>
</mujoco>
